Workbook

Sheet Instructions
A1: Instructions — Event Frequency Analysis
A3: 1) LOGGING EVENTS
A4: Just append a new row at the bottom of the "RawData" sheet.
A5: Date as DD.MM.YYYY (e.g. 09.05.2026), Time as HH:MM (e.g. 14:30).
A6: The "Slot" column fills in automatically (half-hour slot 0 to 47).
A7: The "Counter" column is optional and is not used in the analysis.
A8: Each row counts as 1 event.
A10: 2) ADDING A NEW DAY TO THE HEATMAP
A11: In the "Heatmap Day x Time" sheet, 80 reserve rows with ready formulas
A12: are prepared below the existing data.
A13: Just enter the date in column A — all 48 half-hour columns, the daily total
A14: and the weekday calculate automatically.
... A35: whatever you are counting (visitors, button presses, errors, sales, etc.).

Sheet Heatmap Day x Time
A1: Event Heatmap: Day × Time (30-minute resolution)
A2: Updates automatically from the RawData table. Colour scale: light = few, dark green = many.
A4: Date | B4: Weekday | C4: 00:00 | D4: 00:30 | E4: 01:00 | F4: 01:30 | G4: 02:00 | H4: 02:30 | I4: 03:00 | J4: 03:30 | K4: 04:00 | L4: 04:30 | M4: 05:00 | N4: 05:30 | O4: 06:00 | P4: 06:30 | Q4: 07:00 | R4: 07:30 | S4: 08:00 | T4: 08:30 | U4: 09:00 | V4: 09:30 | W4: 10:00 | X4: 10:30 | Y4: 11:00 | Z4: 11:30 | AA4: 12:00 | AB4: 12:30 | AC4: 13:00 | AD4: 13:30 | AE4: 14:00 | AF4: 14:30 | AG4: 15:00 | AH4: 15:30 | AI4: 16:00 | AJ4: 16:30 | AK4: 17:00 | AL4: 17:30 | AM4: 18:00 | AN4: 18:30 | AO4: 19:00 | AP4: 19:30 | AQ4: 20:00 | AR4: 20:30 | AS4: 21:00 | AT4: 21:30 | AU4: 22:00 | AV4: 22:30 | AW4: 23:00 | AX4: 23:30 | AY4: Daily Total
A5: 46150 | B5: =IF(A5="","",CHOOSE(WEEKDAY(A5,2),"Monday","Tuesday","Wednesday","Thursday","Friday","Saturday","Sunday")) -> Friday | C5: =IF($A5="","",COUNTIFS(RawData[Date],$A5,RawData[Slot],0)) -> 0 | D5: =IF($A5="","",COUNTIFS(RawData[Date],$A5,RawData[Slot],1)) -> 0 | E5: =IF($A5="","",COUNTIFS(RawData[Date],$A5,RawData[Slot],2)) -> 0 | F5: =IF($A5="","",COUNTIFS(RawData[Date],$A5,RawData[Slot],3)) -> 0 | G5: =IF($A5="","",COUNTIFS(RawData[Date],$A5,RawData[Slot],4)) -> 0 | H5: =IF($A5="","",COUNTIFS(RawData[Date],$A5,RawData[Slot],5)) -> 0 | I5: =IF($A5="","",COUNTIFS(RawData[Date],$A5,RawData[Slot],6)) -> 0 | J5: =IF($A5="","",COUNTIFS(RawData[Date],$A5,RawData[Slot],7)) -> 0 | K5: =IF($A5="","",COUNTIFS(RawData[Date],$A5,RawData[Slot],8)) -> 0 | L5: =IF($A5="","",COUNTIFS(RawData[Date],$A5,RawData[Slot],9)) -> 0 | M5: =IF($A5="","",COUNTIFS(RawData[Date],$A5,RawData[Slot],10)) -> 0 | N5: =IF($A5="","",COUNTIFS(RawData[Date],$A5,RawData[Slot],11)) -> 0 | O5: =IF($A5="","",COUNTIFS(RawData[Date],$A5,RawData[Slot],12)) -> 0 | P5: =IF($A5="","",COUNTIFS(RawData[Date],$A5,RawData[Slot],13)) -> 0 | Q5: =IF($A5="","",COUNTIFS(RawData[Date],$A5,RawData[Slot],14)) -> 0 | R5: =IF($A5="","",COUNTIFS(RawData[Date],$A5,RawData[Slot],15)) -> 0 | S5: =IF($A5="","",COUNTIFS(RawData[Date],$A5,RawData[Slot],16)) -> 0 | T5: =IF($A5="","",COUNTIFS(RawData[Date],$A5,RawData[Slot],17)) -> 0 | U5: =IF($A5="","",COUNTIFS(RawData[Date],$A5,RawData[Slot],18)) -> 0 | V5: =IF($A5="","",COUNTIFS(RawData[Date],$A5,RawData[Slot],19)) -> 6 | W5: =IF($A5="","",COUNTIFS(RawData[Date],$A5,RawData[Slot],20)) -> 3 | X5: =IF($A5="","",COUNTIFS(RawData[Date],$A5,RawData[Slot],21)) -> 1 | Y5: =IF($A5="","",COUNTIFS(RawData[Date],$A5,RawData[Slot],22)) -> 2 | Z5: =IF($A5="","",COUNTIFS(RawData[Date],$A5,RawData[Slot],23)) -> 2 | AA5: =IF($A5="","",COUNTIFS(RawData[Date],$A5,RawData[Slot],24)) -> 0 | AB5: =IF($A5="","",COUNTIFS(RawData[Date],$A5,RawData[Slot],25)) -> 3 | AC5: =IF($A5="","",COUNTIFS(RawData[Date],$A5,RawData[Slot],26)) -> 1 | AD5: =IF($A5="","",COUNTIFS(RawData[Date],$A5,RawData[Slot],27)) -> 0 | AE5: =IF($A5="","",COUNTIFS(RawData[Date],$A5,RawData[Slot],28)) -> 0 | AF5: =IF($A5="","",COUNTIFS(RawData[Date],$A5,RawData[Slot],29)) -> 0 | AG5: =IF($A5="","",COUNTIFS(RawData[Date],$A5,RawData[Slot],30)) -> 0 | AH5: =IF($A5="","",COUNTIFS(RawData[Date],$A5,RawData[Slot],31)) -> 5 | AI5: =IF($A5="","",COUNTIFS(RawData[Date],$A5,RawData[Slot],32)) -> 1 | AJ5: =IF($A5="","",COUNTIFS(RawData[Date],$A5,RawData[Slot],33)) -> 2 | AK5: =IF($A5="","",COUNTIFS(RawData[Date],$A5,RawData[Slot],34)) -> 0 | AL5: =IF($A5="","",COUNTIFS(RawData[Date],$A5,RawData[Slot],35)) -> 0 | AM5: =IF($A5="","",COUNTIFS(RawData[Date],$A5,RawData[Slot],36)) -> 0 | AN5: =IF($A5="","",COUNTIFS(RawData[Date],$A5,RawData[Slot],37)) -> 0 | AO5: =IF($A5="","",COUNTIFS(RawData[Date],$A5,RawData[Slot],38)) -> 0 | AP5: =IF($A5="","",COUNTIFS(RawData[Date],$A5,RawData[Slot],39)) -> 0 | AQ5: =IF($A5="","",COUNTIFS(RawData[Date],$A5,RawData[Slot],40)) -> 0 | AR5: =IF($A5="","",COUNTIFS(RawData[Date],$A5,RawData[Slot],41)) -> 0 | AS5: =IF($A5="","",COUNTIFS(RawData[Date],$A5,RawData[Slot],42)) -> 0 | AT5: =IF($A5="","",COUNTIFS(RawData[Date],$A5,RawData[Slot],43)) -> 0 | AU5: =IF($A5="","",COUNTIFS(RawData[Date],$A5,RawData[Slot],44)) -> 0 | AV5: =IF($A5="","",COUNTIFS(RawData[Date],$A5,RawData[Slot],45)) -> 0 | AW5: =IF($A5="","",COUNTIFS(RawData[Date],$A5,RawData[Slot],46)) -> 0 | AX5: =IF($A5="","",COUNTIFS(RawData[Date],$A5,RawData[Slot],47)) -> 0 | AY5: =IF(A5="","",SUM(C5:AX5)) -> 26
A6: 46153 | B6: =IF(A6="","",CHOOSE(WEEKDAY(A6,2),"Monday","Tuesday","Wednesday","Thursday","Friday","Saturday","Sunday")) -> Monday | C6: =IF($A6="","",COUNTIFS(RawData[Date],$A6,RawData[Slot],0)) -> 0 | D6: =IF($A6="","",COUNTIFS(RawData[Date],$A6,RawData[Slot],1)) -> 0 | E6: =IF($A6="","",COUNTIFS(RawData[Date],$A6,RawData[Slot],2)) -> 0 | F6: =IF($A6="","",COUNTIFS(RawData[Date],$A6,RawData[Slot],3)) -> 0 | G6: =IF($A6="","",COUNTIFS(RawData[Date],$A6,RawData[Slot],4)) -> 0 | H6: =IF($A6="","",COUNTIFS(RawData[Date],$A6,RawData[Slot],5)) -> 0 | I6: =IF($A6="","",COUNTIFS(RawData[Date],$A6,RawData[Slot],6)) -> 0 | J6: =IF($A6="","",COUNTIFS(RawData[Date],$A6,RawData[Slot],7)) -> 0 | K6: =IF($A6="","",COUNTIFS(RawData[Date],$A6,RawData[Slot],8)) -> 0 | L6: =IF($A6="","",COUNTIFS(RawData[Date],$A6,RawData[Slot],9)) -> 0 | M6: =IF($A6="","",COUNTIFS(RawData[Date],$A6,RawData[Slot],10)) -> 0 | N6: =IF($A6="","",COUNTIFS(RawData[Date],$A6,RawData[Slot],11)) -> 0 | O6: =IF($A6="","",COUNTIFS(RawData[Date],$A6,RawData[Slot],12)) -> 0 | P6: =IF($A6="","",COUNTIFS(RawData[Date],$A6,RawData[Slot],13)) -> 0 | Q6: =IF($A6="","",COUNTIFS(RawData[Date],$A6,RawData[Slot],14)) -> 0 | R6: =IF($A6="","",COUNTIFS(RawData[Date],$A6,RawData[Slot],15)) -> 0 | S6: =IF($A6="","",COUNTIFS(RawData[Date],$A6,RawData[Slot],16)) -> 0 | T6: =IF($A6="","",COUNTIFS(RawData[Date],$A6,RawData[Slot],17)) -> 0 | U6: =IF($A6="","",COUNTIFS(RawData[Date],$A6,RawData[Slot],18)) -> 0 | V6: =IF($A6="","",COUNTIFS(RawData[Date],$A6,RawData[Slot],19)) -> 0 | W6: =IF($A6="","",COUNTIFS(RawData[Date],$A6,RawData[Slot],20)) -> 0 | X6: =IF($A6="","",COUNTIFS(RawData[Date],$A6,RawData[Slot],21)) -> 0 | Y6: =IF($A6="","",COUNTIFS(RawData[Date],$A6,RawData[Slot],22)) -> 0 | Z6: =IF($A6="","",COUNTIFS(RawData[Date],$A6,RawData[Slot],23)) -> 0 | AA6: =IF($A6="","",COUNTIFS(RawData[Date],$A6,RawData[Slot],24)) -> 0 | AB6: =IF($A6="","",COUNTIFS(RawData[Date],$A6,RawData[Slot],25)) -> 0 | AC6: =IF($A6="","",COUNTIFS(RawData[Date],$A6,RawData[Slot],26)) -> 0 | AD6: =IF($A6="","",COUNTIFS(RawData[Date],$A6,RawData[Slot],27)) -> 0 | AE6: =IF($A6="","",COUNTIFS(RawData[Date],$A6,RawData[Slot],28)) -> 0 | AF6: =IF($A6="","",COUNTIFS(RawData[Date],$A6,RawData[Slot],29)) -> 0 | AG6: =IF($A6="","",COUNTIFS(RawData[Date],$A6,RawData[Slot],30)) -> 0 | AH6: =IF($A6="","",COUNTIFS(RawData[Date],$A6,RawData[Slot],31)) -> 0 | AI6: =IF($A6="","",COUNTIFS(RawData[Date],$A6,RawData[Slot],32)) -> 0 | AJ6: =IF($A6="","",COUNTIFS(RawData[Date],$A6,RawData[Slot],33)) -> 0 | AK6: =IF($A6="","",COUNTIFS(RawData[Date],$A6,RawData[Slot],34)) -> 0 | AL6: =IF($A6="","",COUNTIFS(RawData[Date],$A6,RawData[Slot],35)) -> 0 | AM6: =IF($A6="","",COUNTIFS(RawData[Date],$A6,RawData[Slot],36)) -> 0 | AN6: =IF($A6="","",COUNTIFS(RawData[Date],$A6,RawData[Slot],37)) -> 0 | AO6: =IF($A6="","",COUNTIFS(RawData[Date],$A6,RawData[Slot],38)) -> 0 | AP6: =IF($A6="","",COUNTIFS(RawData[Date],$A6,RawData[Slot],39)) -> 0 | AQ6: =IF($A6="","",COUNTIFS(RawData[Date],$A6,RawData[Slot],40)) -> 0 | AR6: =IF($A6="","",COUNTIFS(RawData[Date],$A6,RawData[Slot],41)) -> 0 | AS6: =IF($A6="","",COUNTIFS(RawData[Date],$A6,RawData[Slot],42)) -> 0 | AT6: =IF($A6="","",COUNTIFS(RawData[Date],$A6,RawData[Slot],43)) -> 0 | AU6: =IF($A6="","",COUNTIFS(RawData[Date],$A6,RawData[Slot],44)) -> 0 | AV6: =IF($A6="","",COUNTIFS(RawData[Date],$A6,RawData[Slot],45)) -> 0 | AW6: =IF($A6="","",COUNTIFS(RawData[Date],$A6,RawData[Slot],46)) -> 0 | AX6: =IF($A6="","",COUNTIFS(RawData[Date],$A6,RawData[Slot],47)) -> 0 | AY6: =IF(A6="","",SUM(C6:AX6)) -> 0
A7: 46154 | B7: =IF(A7="","",CHOOSE(WEEKDAY(A7,2),"Monday","Tuesday","Wednesday","Thursday","Friday","Saturday","Sunday")) -> Tuesday | C7: =IF($A7="","",COUNTIFS(RawData[Date],$A7,RawData[Slot],0)) -> 0 | D7: =IF($A7="","",COUNTIFS(RawData[Date],$A7,RawData[Slot],1)) -> 0 | E7: =IF($A7="","",COUNTIFS(RawData[Date],$A7,RawData[Slot],2)) -> 0 | F7: =IF($A7="","",COUNTIFS(RawData[Date],$A7,RawData[Slot],3)) -> 0 | G7: =IF($A7="","",COUNTIFS(RawData[Date],$A7,RawData[Slot],4)) -> 0 | H7: =IF($A7="","",COUNTIFS(RawData[Date],$A7,RawData[Slot],5)) -> 0 | I7: =IF($A7="","",COUNTIFS(RawData[Date],$A7,RawData[Slot],6)) -> 0 | J7: =IF($A7="","",COUNTIFS(RawData[Date],$A7,RawData[Slot],7)) -> 0 | K7: =IF($A7="","",COUNTIFS(RawData[Date],$A7,RawData[Slot],8)) -> 0 | L7: =IF($A7="","",COUNTIFS(RawData[Date],$A7,RawData[Slot],9)) -> 0 | M7: =IF($A7="","",COUNTIFS(RawData[Date],$A7,RawData[Slot],10)) -> 0 | N7: =IF($A7="","",COUNTIFS(RawData[Date],$A7,RawData[Slot],11)) -> 0 | O7: =IF($A7="","",COUNTIFS(RawData[Date],$A7,RawData[Slot],12)) -> 0 | P7: =IF($A7="","",COUNTIFS(RawData[Date],$A7,RawData[Slot],13)) -> 0 | Q7: =IF($A7="","",COUNTIFS(RawData[Date],$A7,RawData[Slot],14)) -> 0 | R7: =IF($A7="","",COUNTIFS(RawData[Date],$A7,RawData[Slot],15)) -> 0 | S7: =IF($A7="","",COUNTIFS(RawData[Date],$A7,RawData[Slot],16)) -> 0 | T7: =IF($A7="","",COUNTIFS(RawData[Date],$A7,RawData[Slot],17)) -> 0 | U7: =IF($A7="","",COUNTIFS(RawData[Date],$A7,RawData[Slot],18)) -> 0 | V7: =IF($A7="","",COUNTIFS(RawData[Date],$A7,RawData[Slot],19)) -> 0 | W7: =IF($A7="","",COUNTIFS(RawData[Date],$A7,RawData[Slot],20)) -> 0 | X7: =IF($A7="","",COUNTIFS(RawData[Date],$A7,RawData[Slot],21)) -> 0 | Y7: =IF($A7="","",COUNTIFS(RawData[Date],$A7,RawData[Slot],22)) -> 0 | Z7: =IF($A7="","",COUNTIFS(RawData[Date],$A7,RawData[Slot],23)) -> 0 | AA7: =IF($A7="","",COUNTIFS(RawData[Date],$A7,RawData[Slot],24)) -> 0 | AB7: =IF($A7="","",COUNTIFS(RawData[Date],$A7,RawData[Slot],25)) -> 0 | AC7: =IF($A7="","",COUNTIFS(RawData[Date],$A7,RawData[Slot],26)) -> 0 | AD7: =IF($A7="","",COUNTIFS(RawData[Date],$A7,RawData[Slot],27)) -> 0 | AE7: =IF($A7="","",COUNTIFS(RawData[Date],$A7,RawData[Slot],28)) -> 0 | AF7: =IF($A7="","",COUNTIFS(RawData[Date],$A7,RawData[Slot],29)) -> 0 | AG7: =IF($A7="","",COUNTIFS(RawData[Date],$A7,RawData[Slot],30)) -> 0 | AH7: =IF($A7="","",COUNTIFS(RawData[Date],$A7,RawData[Slot],31)) -> 0 | AI7: =IF($A7="","",COUNTIFS(RawData[Date],$A7,RawData[Slot],32)) -> 0 | AJ7: =IF($A7="","",COUNTIFS(RawData[Date],$A7,RawData[Slot],33)) -> 0 | AK7: =IF($A7="","",COUNTIFS(RawData[Date],$A7,RawData[Slot],34)) -> 0 | AL7: =IF($A7="","",COUNTIFS(RawData[Date],$A7,RawData[Slot],35)) -> 0 | AM7: =IF($A7="","",COUNTIFS(RawData[Date],$A7,RawData[Slot],36)) -> 0 | AN7: =IF($A7="","",COUNTIFS(RawData[Date],$A7,RawData[Slot],37)) -> 0 | AO7: =IF($A7="","",COUNTIFS(RawData[Date],$A7,RawData[Slot],38)) -> 0 | AP7: =IF($A7="","",COUNTIFS(RawData[Date],$A7,RawData[Slot],39)) -> 0 | AQ7: =IF($A7="","",COUNTIFS(RawData[Date],$A7,RawData[Slot],40)) -> 0 | AR7: =IF($A7="","",COUNTIFS(RawData[Date],$A7,RawData[Slot],41)) -> 0 | AS7: =IF($A7="","",COUNTIFS(RawData[Date],$A7,RawData[Slot],42)) -> 0 | AT7: =IF($A7="","",COUNTIFS(RawData[Date],$A7,RawData[Slot],43)) -> 0 | AU7: =IF($A7="","",COUNTIFS(RawData[Date],$A7,RawData[Slot],44)) -> 0 | AV7: =IF($A7="","",COUNTIFS(RawData[Date],$A7,RawData[Slot],45)) -> 0 | AW7: =IF($A7="","",COUNTIFS(RawData[Date],$A7,RawData[Slot],46)) -> 0 | AX7: =IF($A7="","",COUNTIFS(RawData[Date],$A7,RawData[Slot],47)) -> 0 | AY7: =IF(A7="","",SUM(C7:AX7)) -> 0
A8: 46155 | B8: =IF(A8="","",CHOOSE(WEEKDAY(A8,2),"Monday","Tuesday","Wednesday","Thursday","Friday","Saturday","Sunday")) -> Wednesday | C8: =IF($A8="","",COUNTIFS(RawData[Date],$A8,RawData[Slot],0)) -> 0 | D8: =IF($A8="","",COUNTIFS(RawData[Date],$A8,RawData[Slot],1)) -> 0 | E8: =IF($A8="","",COUNTIFS(RawData[Date],$A8,RawData[Slot],2)) -> 0 | F8: =IF($A8="","",COUNTIFS(RawData[Date],$A8,RawData[Slot],3)) -> 0 | G8: =IF($A8="","",COUNTIFS(RawData[Date],$A8,RawData[Slot],4)) -> 0 | H8: =IF($A8="","",COUNTIFS(RawData[Date],$A8,RawData[Slot],5)) -> 0 | I8: =IF($A8="","",COUNTIFS(RawData[Date],$A8,RawData[Slot],6)) -> 0 | J8: =IF($A8="","",COUNTIFS(RawData[Date],$A8,RawData[Slot],7)) -> 0 | K8: =IF($A8="","",COUNTIFS(RawData[Date],$A8,RawData[Slot],8)) -> 0 | L8: =IF($A8="","",COUNTIFS(RawData[Date],$A8,RawData[Slot],9)) -> 0 | M8: =IF($A8="","",COUNTIFS(RawData[Date],$A8,RawData[Slot],10)) -> 0 | N8: =IF($A8="","",COUNTIFS(RawData[Date],$A8,RawData[Slot],11)) -> 0 | O8: =IF($A8="","",COUNTIFS(RawData[Date],$A8,RawData[Slot],12)) -> 0 | P8: =IF($A8="","",COUNTIFS(RawData[Date],$A8,RawData[Slot],13)) -> 0 | Q8: =IF($A8="","",COUNTIFS(RawData[Date],$A8,RawData[Slot],14)) -> 0 | R8: =IF($A8="","",COUNTIFS(RawData[Date],$A8,RawData[Slot],15)) -> 0 | S8: =IF($A8="","",COUNTIFS(RawData[Date],$A8,RawData[Slot],16)) -> 0 | T8: =IF($A8="","",COUNTIFS(RawData[Date],$A8,RawData[Slot],17)) -> 0 | U8: =IF($A8="","",COUNTIFS(RawData[Date],$A8,RawData[Slot],18)) -> 0 | V8: =IF($A8="","",COUNTIFS(RawData[Date],$A8,RawData[Slot],19)) -> 0 | W8: =IF($A8="","",COUNTIFS(RawData[Date],$A8,RawData[Slot],20)) -> 0 | X8: =IF($A8="","",COUNTIFS(RawData[Date],$A8,RawData[Slot],21)) -> 0 | Y8: =IF($A8="","",COUNTIFS(RawData[Date],$A8,RawData[Slot],22)) -> 0 | Z8: =IF($A8="","",COUNTIFS(RawData[Date],$A8,RawData[Slot],23)) -> 0 | AA8: =IF($A8="","",COUNTIFS(RawData[Date],$A8,RawData[Slot],24)) -> 0 | AB8: =IF($A8="","",COUNTIFS(RawData[Date],$A8,RawData[Slot],25)) -> 0 | AC8: =IF($A8="","",COUNTIFS(RawData[Date],$A8,RawData[Slot],26)) -> 0 | AD8: =IF($A8="","",COUNTIFS(RawData[Date],$A8,RawData[Slot],27)) -> 0 | AE8: =IF($A8="","",COUNTIFS(RawData[Date],$A8,RawData[Slot],28)) -> 0 | AF8: =IF($A8="","",COUNTIFS(RawData[Date],$A8,RawData[Slot],29)) -> 0 | AG8: =IF($A8="","",COUNTIFS(RawData[Date],$A8,RawData[Slot],30)) -> 0 | AH8: =IF($A8="","",COUNTIFS(RawData[Date],$A8,RawData[Slot],31)) -> 0 | AI8: =IF($A8="","",COUNTIFS(RawData[Date],$A8,RawData[Slot],32)) -> 0 | AJ8: =IF($A8="","",COUNTIFS(RawData[Date],$A8,RawData[Slot],33)) -> 0 | AK8: =IF($A8="","",COUNTIFS(RawData[Date],$A8,RawData[Slot],34)) -> 0 | AL8: =IF($A8="","",COUNTIFS(RawData[Date],$A8,RawData[Slot],35)) -> 0 | AM8: =IF($A8="","",COUNTIFS(RawData[Date],$A8,RawData[Slot],36)) -> 0 | AN8: =IF($A8="","",COUNTIFS(RawData[Date],$A8,RawData[Slot],37)) -> 0 | AO8: =IF($A8="","",COUNTIFS(RawData[Date],$A8,RawData[Slot],38)) -> 0 | AP8: =IF($A8="","",COUNTIFS(RawData[Date],$A8,RawData[Slot],39)) -> 0 | AQ8: =IF($A8="","",COUNTIFS(RawData[Date],$A8,RawData[Slot],40)) -> 0 | AR8: =IF($A8="","",COUNTIFS(RawData[Date],$A8,RawData[Slot],41)) -> 0 | AS8: =IF($A8="","",COUNTIFS(RawData[Date],$A8,RawData[Slot],42)) -> 0 | AT8: =IF($A8="","",COUNTIFS(RawData[Date],$A8,RawData[Slot],43)) -> 0 | AU8: =IF($A8="","",COUNTIFS(RawData[Date],$A8,RawData[Slot],44)) -> 0 | AV8: =IF($A8="","",COUNTIFS(RawData[Date],$A8,RawData[Slot],45)) -> 0 | AW8: =IF($A8="","",COUNTIFS(RawData[Date],$A8,RawData[Slot],46)) -> 0 | AX8: =IF($A8="","",COUNTIFS(RawData[Date],$A8,RawData[Slot],47)) -> 0 | AY8: =IF(A8="","",SUM(C8:AX8)) -> 0
A9: 46156 | B9: =IF(A9="","",CHOOSE(WEEKDAY(A9,2),"Monday","Tuesday","Wednesday","Thursday","Friday","Saturday","Sunday")) -> Thursday | C9: =IF($A9="","",COUNTIFS(RawData[Date],$A9,RawData[Slot],0)) -> 0 | D9: =IF($A9="","",COUNTIFS(RawData[Date],$A9,RawData[Slot],1)) -> 0 | E9: =IF($A9="","",COUNTIFS(RawData[Date],$A9,RawData[Slot],2)) -> 0 | F9: =IF($A9="","",COUNTIFS(RawData[Date],$A9,RawData[Slot],3)) -> 0 | G9: =IF($A9="","",COUNTIFS(RawData[Date],$A9,RawData[Slot],4)) -> 0 | H9: =IF($A9="","",COUNTIFS(RawData[Date],$A9,RawData[Slot],5)) -> 0 | I9: =IF($A9="","",COUNTIFS(RawData[Date],$A9,RawData[Slot],6)) -> 0 | J9: =IF($A9="","",COUNTIFS(RawData[Date],$A9,RawData[Slot],7)) -> 0 | K9: =IF($A9="","",COUNTIFS(RawData[Date],$A9,RawData[Slot],8)) -> 0 | L9: =IF($A9="","",COUNTIFS(RawData[Date],$A9,RawData[Slot],9)) -> 0 | M9: =IF($A9="","",COUNTIFS(RawData[Date],$A9,RawData[Slot],10)) -> 0 | N9: =IF($A9="","",COUNTIFS(RawData[Date],$A9,RawData[Slot],11)) -> 0 | O9: =IF($A9="","",COUNTIFS(RawData[Date],$A9,RawData[Slot],12)) -> 0 | P9: =IF($A9="","",COUNTIFS(RawData[Date],$A9,RawData[Slot],13)) -> 0 | Q9: =IF($A9="","",COUNTIFS(RawData[Date],$A9,RawData[Slot],14)) -> 0 | R9: =IF($A9="","",COUNTIFS(RawData[Date],$A9,RawData[Slot],15)) -> 0 | S9: =IF($A9="","",COUNTIFS(RawData[Date],$A9,RawData[Slot],16)) -> 0 | T9: =IF($A9="","",COUNTIFS(RawData[Date],$A9,RawData[Slot],17)) -> 0 | U9: =IF($A9="","",COUNTIFS(RawData[Date],$A9,RawData[Slot],18)) -> 0 | V9: =IF($A9="","",COUNTIFS(RawData[Date],$A9,RawData[Slot],19)) -> 0 | W9: =IF($A9="","",COUNTIFS(RawData[Date],$A9,RawData[Slot],20)) -> 0 | X9: =IF($A9="","",COUNTIFS(RawData[Date],$A9,RawData[Slot],21)) -> 0 | Y9: =IF($A9="","",COUNTIFS(RawData[Date],$A9,RawData[Slot],22)) -> 0 | Z9: =IF($A9="","",COUNTIFS(RawData[Date],$A9,RawData[Slot],23)) -> 0 | AA9: =IF($A9="","",COUNTIFS(RawData[Date],$A9,RawData[Slot],24)) -> 0 | AB9: =IF($A9="","",COUNTIFS(RawData[Date],$A9,RawData[Slot],25)) -> 0 | AC9: =IF($A9="","",COUNTIFS(RawData[Date],$A9,RawData[Slot],26)) -> 0 | AD9: =IF($A9="","",COUNTIFS(RawData[Date],$A9,RawData[Slot],27)) -> 0 | AE9: =IF($A9="","",COUNTIFS(RawData[Date],$A9,RawData[Slot],28)) -> 0 | AF9: =IF($A9="","",COUNTIFS(RawData[Date],$A9,RawData[Slot],29)) -> 0 | AG9: =IF($A9="","",COUNTIFS(RawData[Date],$A9,RawData[Slot],30)) -> 0 | AH9: =IF($A9="","",COUNTIFS(RawData[Date],$A9,RawData[Slot],31)) -> 0 | AI9: =IF($A9="","",COUNTIFS(RawData[Date],$A9,RawData[Slot],32)) -> 0 | AJ9: =IF($A9="","",COUNTIFS(RawData[Date],$A9,RawData[Slot],33)) -> 0 | AK9: =IF($A9="","",COUNTIFS(RawData[Date],$A9,RawData[Slot],34)) -> 0 | AL9: =IF($A9="","",COUNTIFS(RawData[Date],$A9,RawData[Slot],35)) -> 0 | AM9: =IF($A9="","",COUNTIFS(RawData[Date],$A9,RawData[Slot],36)) -> 0 | AN9: =IF($A9="","",COUNTIFS(RawData[Date],$A9,RawData[Slot],37)) -> 0 | AO9: =IF($A9="","",COUNTIFS(RawData[Date],$A9,RawData[Slot],38)) -> 0 | AP9: =IF($A9="","",COUNTIFS(RawData[Date],$A9,RawData[Slot],39)) -> 0 | AQ9: =IF($A9="","",COUNTIFS(RawData[Date],$A9,RawData[Slot],40)) -> 0 | AR9: =IF($A9="","",COUNTIFS(RawData[Date],$A9,RawData[Slot],41)) -> 0 | AS9: =IF($A9="","",COUNTIFS(RawData[Date],$A9,RawData[Slot],42)) -> 0 | AT9: =IF($A9="","",COUNTIFS(RawData[Date],$A9,RawData[Slot],43)) -> 0 | AU9: =IF($A9="","",COUNTIFS(RawData[Date],$A9,RawData[Slot],44)) -> 0 | AV9: =IF($A9="","",COUNTIFS(RawData[Date],$A9,RawData[Slot],45)) -> 0 | AW9: =IF($A9="","",COUNTIFS(RawData[Date],$A9,RawData[Slot],46)) -> 0 | AX9: =IF($A9="","",COUNTIFS(RawData[Date],$A9,RawData[Slot],47)) -> 0 | AY9: =IF(A9="","",SUM(C9:AX9)) -> 0
A10: 46157 | B10: =IF(A10="","",CHOOSE(WEEKDAY(A10,2),"Monday","Tuesday","Wednesday","Thursday","Friday","Saturday","Sunday")) -> Friday | C10: =IF($A10="","",COUNTIFS(RawData[Date],$A10,RawData[Slot],0)) -> 0 | D10: =IF($A10="","",COUNTIFS(RawData[Date],$A10,RawData[Slot],1)) -> 0 | E10: =IF($A10="","",COUNTIFS(RawData[Date],$A10,RawData[Slot],2)) -> 0 | F10: =IF($A10="","",COUNTIFS(RawData[Date],$A10,RawData[Slot],3)) -> 0 | G10: =IF($A10="","",COUNTIFS(RawData[Date],$A10,RawData[Slot],4)) -> 0 | H10: =IF($A10="","",COUNTIFS(RawData[Date],$A10,RawData[Slot],5)) -> 0 | I10: =IF($A10="","",COUNTIFS(RawData[Date],$A10,RawData[Slot],6)) -> 0 | J10: =IF($A10="","",COUNTIFS(RawData[Date],$A10,RawData[Slot],7)) -> 0 | K10: =IF($A10="","",COUNTIFS(RawData[Date],$A10,RawData[Slot],8)) -> 0 | L10: =IF($A10="","",COUNTIFS(RawData[Date],$A10,RawData[Slot],9)) -> 0 | M10: =IF($A10="","",COUNTIFS(RawData[Date],$A10,RawData[Slot],10)) -> 0 | N10: =IF($A10="","",COUNTIFS(RawData[Date],$A10,RawData[Slot],11)) -> 0 | O10: =IF($A10="","",COUNTIFS(RawData[Date],$A10,RawData[Slot],12)) -> 0 | P10: =IF($A10="","",COUNTIFS(RawData[Date],$A10,RawData[Slot],13)) -> 0 | Q10: =IF($A10="","",COUNTIFS(RawData[Date],$A10,RawData[Slot],14)) -> 0 | R10: =IF($A10="","",COUNTIFS(RawData[Date],$A10,RawData[Slot],15)) -> 0 | S10: =IF($A10="","",COUNTIFS(RawData[Date],$A10,RawData[Slot],16)) -> 0 | T10: =IF($A10="","",COUNTIFS(RawData[Date],$A10,RawData[Slot],17)) -> 0 | U10: =IF($A10="","",COUNTIFS(RawData[Date],$A10,RawData[Slot],18)) -> 0 | V10: =IF($A10="","",COUNTIFS(RawData[Date],$A10,RawData[Slot],19)) -> 0 | W10: =IF($A10="","",COUNTIFS(RawData[Date],$A10,RawData[Slot],20)) -> 0 | X10: =IF($A10="","",COUNTIFS(RawData[Date],$A10,RawData[Slot],21)) -> 0 | Y10: =IF($A10="","",COUNTIFS(RawData[Date],$A10,RawData[Slot],22)) -> 0 | Z10: =IF($A10="","",COUNTIFS(RawData[Date],$A10,RawData[Slot],23)) -> 0 | AA10: =IF($A10="","",COUNTIFS(RawData[Date],$A10,RawData[Slot],24)) -> 0 | AB10: =IF($A10="","",COUNTIFS(RawData[Date],$A10,RawData[Slot],25)) -> 0 | AC10: =IF($A10="","",COUNTIFS(RawData[Date],$A10,RawData[Slot],26)) -> 0 | AD10: =IF($A10="","",COUNTIFS(RawData[Date],$A10,RawData[Slot],27)) -> 0 | AE10: =IF($A10="","",COUNTIFS(RawData[Date],$A10,RawData[Slot],28)) -> 0 | AF10: =IF($A10="","",COUNTIFS(RawData[Date],$A10,RawData[Slot],29)) -> 0 | AG10: =IF($A10="","",COUNTIFS(RawData[Date],$A10,RawData[Slot],30)) -> 0 | AH10: =IF($A10="","",COUNTIFS(RawData[Date],$A10,RawData[Slot],31)) -> 0 | AI10: =IF($A10="","",COUNTIFS(RawData[Date],$A10,RawData[Slot],32)) -> 0 | AJ10: =IF($A10="","",COUNTIFS(RawData[Date],$A10,RawData[Slot],33)) -> 0 | AK10: =IF($A10="","",COUNTIFS(RawData[Date],$A10,RawData[Slot],34)) -> 0 | AL10: =IF($A10="","",COUNTIFS(RawData[Date],$A10,RawData[Slot],35)) -> 0 | AM10: =IF($A10="","",COUNTIFS(RawData[Date],$A10,RawData[Slot],36)) -> 0 | AN10: =IF($A10="","",COUNTIFS(RawData[Date],$A10,RawData[Slot],37)) -> 0 | AO10: =IF($A10="","",COUNTIFS(RawData[Date],$A10,RawData[Slot],38)) -> 0 | AP10: =IF($A10="","",COUNTIFS(RawData[Date],$A10,RawData[Slot],39)) -> 0 | AQ10: =IF($A10="","",COUNTIFS(RawData[Date],$A10,RawData[Slot],40)) -> 0 | AR10: =IF($A10="","",COUNTIFS(RawData[Date],$A10,RawData[Slot],41)) -> 0 | AS10: =IF($A10="","",COUNTIFS(RawData[Date],$A10,RawData[Slot],42)) -> 0 | AT10: =IF($A10="","",COUNTIFS(RawData[Date],$A10,RawData[Slot],43)) -> 0 | AU10: =IF($A10="","",COUNTIFS(RawData[Date],$A10,RawData[Slot],44)) -> 0 | AV10: =IF($A10="","",COUNTIFS(RawData[Date],$A10,RawData[Slot],45)) -> 0 | AW10: =IF($A10="","",COUNTIFS(RawData[Date],$A10,RawData[Slot],46)) -> 0 | AX10: =IF($A10="","",COUNTIFS(RawData[Date],$A10,RawData[Slot],47)) -> 0 | AY10: =IF(A10="","",SUM(C10:AX10)) -> 0
B11: =IF(A11="","",CHOOSE(WEEKDAY(A11,2),"Monday","Tuesday","Wednesday","Thursday","Friday","Saturday","Sunday")) | C11: =IF($A11="","",COUNTIFS(RawData[Date],$A11,RawData[Slot],0)) | D11: =IF($A11="","",COUNTIFS(RawData[Date],$A11,RawData[Slot],1)) | E11: =IF($A11="","",COUNTIFS(RawData[Date],$A11,RawData[Slot],2)) | F11: =IF($A11="","",COUNTIFS(RawData[Date],$A11,RawData[Slot],3)) | G11: =IF($A11="","",COUNTIFS(RawData[Date],$A11,RawData[Slot],4)) | H11: =IF($A11="","",COUNTIFS(RawData[Date],$A11,RawData[Slot],5)) | I11: =IF($A11="","",COUNTIFS(RawData[Date],$A11,RawData[Slot],6)) | J11: =IF($A11="","",COUNTIFS(RawData[Date],$A11,RawData[Slot],7)) | K11: =IF($A11="","",COUNTIFS(RawData[Date],$A11,RawData[Slot],8)) | L11: =IF($A11="","",COUNTIFS(RawData[Date],$A11,RawData[Slot],9)) | M11: =IF($A11="","",COUNTIFS(RawData[Date],$A11,RawData[Slot],10)) | N11: =IF($A11="","",COUNTIFS(RawData[Date],$A11,RawData[Slot],11)) | O11: =IF($A11="","",COUNTIFS(RawData[Date],$A11,RawData[Slot],12)) | P11: =IF($A11="","",COUNTIFS(RawData[Date],$A11,RawData[Slot],13)) | Q11: =IF($A11="","",COUNTIFS(RawData[Date],$A11,RawData[Slot],14)) | R11: =IF($A11="","",COUNTIFS(RawData[Date],$A11,RawData[Slot],15)) | S11: =IF($A11="","",COUNTIFS(RawData[Date],$A11,RawData[Slot],16)) | T11: =IF($A11="","",COUNTIFS(RawData[Date],$A11,RawData[Slot],17)) | U11: =IF($A11="","",COUNTIFS(RawData[Date],$A11,RawData[Slot],18)) | V11: =IF($A11="","",COUNTIFS(RawData[Date],$A11,RawData[Slot],19)) | W11: =IF($A11="","",COUNTIFS(RawData[Date],$A11,RawData[Slot],20)) | X11: =IF($A11="","",COUNTIFS(RawData[Date],$A11,RawData[Slot],21)) | Y11: =IF($A11="","",COUNTIFS(RawData[Date],$A11,RawData[Slot],22)) | Z11: =IF($A11="","",COUNTIFS(RawData[Date],$A11,RawData[Slot],23)) | AA11: =IF($A11="","",COUNTIFS(RawData[Date],$A11,RawData[Slot],24)) | AB11: =IF($A11="","",COUNTIFS(RawData[Date],$A11,RawData[Slot],25)) | AC11: =IF($A11="","",COUNTIFS(RawData[Date],$A11,RawData[Slot],26)) | AD11: =IF($A11="","",COUNTIFS(RawData[Date],$A11,RawData[Slot],27)) | AE11: =IF($A11="","",COUNTIFS(RawData[Date],$A11,RawData[Slot],28)) | AF11: =IF($A11="","",COUNTIFS(RawData[Date],$A11,RawData[Slot],29)) | AG11: =IF($A11="","",COUNTIFS(RawData[Date],$A11,RawData[Slot],30)) | AH11: =IF($A11="","",COUNTIFS(RawData[Date],$A11,RawData[Slot],31)) | AI11: =IF($A11="","",COUNTIFS(RawData[Date],$A11,RawData[Slot],32)) | AJ11: =IF($A11="","",COUNTIFS(RawData[Date],$A11,RawData[Slot],33)) | AK11: =IF($A11="","",COUNTIFS(RawData[Date],$A11,RawData[Slot],34)) | AL11: =IF($A11="","",COUNTIFS(RawData[Date],$A11,RawData[Slot],35)) | AM11: =IF($A11="","",COUNTIFS(RawData[Date],$A11,RawData[Slot],36)) | AN11: =IF($A11="","",COUNTIFS(RawData[Date],$A11,RawData[Slot],37)) | AO11: =IF($A11="","",COUNTIFS(RawData[Date],$A11,RawData[Slot],38)) | AP11: =IF($A11="","",COUNTIFS(RawData[Date],$A11,RawData[Slot],39)) | AQ11: =IF($A11="","",COUNTIFS(RawData[Date],$A11,RawData[Slot],40)) | AR11: =IF($A11="","",COUNTIFS(RawData[Date],$A11,RawData[Slot],41)) | AS11: =IF($A11="","",COUNTIFS(RawData[Date],$A11,RawData[Slot],42)) | AT11: =IF($A11="","",COUNTIFS(RawData[Date],$A11,RawData[Slot],43)) | AU11: =IF($A11="","",COUNTIFS(RawData[Date],$A11,RawData[Slot],44)) | AV11: =IF($A11="","",COUNTIFS(RawData[Date],$A11,RawData[Slot],45)) | AW11: =IF($A11="","",COUNTIFS(RawData[Date],$A11,RawData[Slot],46)) | AX11: =IF($A11="","",COUNTIFS(RawData[Date],$A11,RawData[Slot],47)) | AY11: =IF(A11="","",SUM(C11:AX11))
B12: =IF(A12="","",CHOOSE(WEEKDAY(A12,2),"Monday","Tuesday","Wednesday","Thursday","Friday","Saturday","Sunday")) | C12: =IF($A12="","",COUNTIFS(RawData[Date],$A12,RawData[Slot],0)) | D12: =IF($A12="","",COUNTIFS(RawData[Date],$A12,RawData[Slot],1)) | E12: =IF($A12="","",COUNTIFS(RawData[Date],$A12,RawData[Slot],2)) | F12: =IF($A12="","",COUNTIFS(RawData[Date],$A12,RawData[Slot],3)) | G12: =IF($A12="","",COUNTIFS(RawData[Date],$A12,RawData[Slot],4)) | H12: =IF($A12="","",COUNTIFS(RawData[Date],$A12,RawData[Slot],5)) | I12: =IF($A12="","",COUNTIFS(RawData[Date],$A12,RawData[Slot],6)) | J12: =IF($A12="","",COUNTIFS(RawData[Date],$A12,RawData[Slot],7)) | K12: =IF($A12="","",COUNTIFS(RawData[Date],$A12,RawData[Slot],8)) | L12: =IF($A12="","",COUNTIFS(RawData[Date],$A12,RawData[Slot],9)) | M12: =IF($A12="","",COUNTIFS(RawData[Date],$A12,RawData[Slot],10)) | N12: =IF($A12="","",COUNTIFS(RawData[Date],$A12,RawData[Slot],11)) | O12: =IF($A12="","",COUNTIFS(RawData[Date],$A12,RawData[Slot],12)) | P12: =IF($A12="","",COUNTIFS(RawData[Date],$A12,RawData[Slot],13)) | Q12: =IF($A12="","",COUNTIFS(RawData[Date],$A12,RawData[Slot],14)) | R12: =IF($A12="","",COUNTIFS(RawData[Date],$A12,RawData[Slot],15)) | S12: =IF($A12="","",COUNTIFS(RawData[Date],$A12,RawData[Slot],16)) | T12: =IF($A12="","",COUNTIFS(RawData[Date],$A12,RawData[Slot],17)) | U12: =IF($A12="","",COUNTIFS(RawData[Date],$A12,RawData[Slot],18)) | V12: =IF($A12="","",COUNTIFS(RawData[Date],$A12,RawData[Slot],19)) | W12: =IF($A12="","",COUNTIFS(RawData[Date],$A12,RawData[Slot],20)) | X12: =IF($A12="","",COUNTIFS(RawData[Date],$A12,RawData[Slot],21)) | Y12: =IF($A12="","",COUNTIFS(RawData[Date],$A12,RawData[Slot],22)) | Z12: =IF($A12="","",COUNTIFS(RawData[Date],$A12,RawData[Slot],23)) | AA12: =IF($A12="","",COUNTIFS(RawData[Date],$A12,RawData[Slot],24)) | AB12: =IF($A12="","",COUNTIFS(RawData[Date],$A12,RawData[Slot],25)) | AC12: =IF($A12="","",COUNTIFS(RawData[Date],$A12,RawData[Slot],26)) | AD12: =IF($A12="","",COUNTIFS(RawData[Date],$A12,RawData[Slot],27)) | AE12: =IF($A12="","",COUNTIFS(RawData[Date],$A12,RawData[Slot],28)) | AF12: =IF($A12="","",COUNTIFS(RawData[Date],$A12,RawData[Slot],29)) | AG12: =IF($A12="","",COUNTIFS(RawData[Date],$A12,RawData[Slot],30)) | AH12: =IF($A12="","",COUNTIFS(RawData[Date],$A12,RawData[Slot],31)) | AI12: =IF($A12="","",COUNTIFS(RawData[Date],$A12,RawData[Slot],32)) | AJ12: =IF($A12="","",COUNTIFS(RawData[Date],$A12,RawData[Slot],33)) | AK12: =IF($A12="","",COUNTIFS(RawData[Date],$A12,RawData[Slot],34)) | AL12: =IF($A12="","",COUNTIFS(RawData[Date],$A12,RawData[Slot],35)) | AM12: =IF($A12="","",COUNTIFS(RawData[Date],$A12,RawData[Slot],36)) | AN12: =IF($A12="","",COUNTIFS(RawData[Date],$A12,RawData[Slot],37)) | AO12: =IF($A12="","",COUNTIFS(RawData[Date],$A12,RawData[Slot],38)) | AP12: =IF($A12="","",COUNTIFS(RawData[Date],$A12,RawData[Slot],39)) | AQ12: =IF($A12="","",COUNTIFS(RawData[Date],$A12,RawData[Slot],40)) | AR12: =IF($A12="","",COUNTIFS(RawData[Date],$A12,RawData[Slot],41)) | AS12: =IF($A12="","",COUNTIFS(RawData[Date],$A12,RawData[Slot],42)) | AT12: =IF($A12="","",COUNTIFS(RawData[Date],$A12,RawData[Slot],43)) | AU12: =IF($A12="","",COUNTIFS(RawData[Date],$A12,RawData[Slot],44)) | AV12: =IF($A12="","",COUNTIFS(RawData[Date],$A12,RawData[Slot],45)) | AW12: =IF($A12="","",COUNTIFS(RawData[Date],$A12,RawData[Slot],46)) | AX12: =IF($A12="","",COUNTIFS(RawData[Date],$A12,RawData[Slot],47)) | AY12: =IF(A12="","",SUM(C12:AX12))
B13: =IF(A13="","",CHOOSE(WEEKDAY(A13,2),"Monday","Tuesday","Wednesday","Thursday","Friday","Saturday","Sunday")) | C13: =IF($A13="","",COUNTIFS(RawData[Date],$A13,RawData[Slot],0)) | D13: =IF($A13="","",COUNTIFS(RawData[Date],$A13,RawData[Slot],1)) | E13: =IF($A13="","",COUNTIFS(RawData[Date],$A13,RawData[Slot],2)) | F13: =IF($A13="","",COUNTIFS(RawData[Date],$A13,RawData[Slot],3)) | G13: =IF($A13="","",COUNTIFS(RawData[Date],$A13,RawData[Slot],4)) | H13: =IF($A13="","",COUNTIFS(RawData[Date],$A13,RawData[Slot],5)) | I13: =IF($A13="","",COUNTIFS(RawData[Date],$A13,RawData[Slot],6)) | J13: =IF($A13="","",COUNTIFS(RawData[Date],$A13,RawData[Slot],7)) | K13: =IF($A13="","",COUNTIFS(RawData[Date],$A13,RawData[Slot],8)) | L13: =IF($A13="","",COUNTIFS(RawData[Date],$A13,RawData[Slot],9)) | M13: =IF($A13="","",COUNTIFS(RawData[Date],$A13,RawData[Slot],10)) | N13: =IF($A13="","",COUNTIFS(RawData[Date],$A13,RawData[Slot],11)) | O13: =IF($A13="","",COUNTIFS(RawData[Date],$A13,RawData[Slot],12)) | P13: =IF($A13="","",COUNTIFS(RawData[Date],$A13,RawData[Slot],13)) | Q13: =IF($A13="","",COUNTIFS(RawData[Date],$A13,RawData[Slot],14)) | R13: =IF($A13="","",COUNTIFS(RawData[Date],$A13,RawData[Slot],15)) | S13: =IF($A13="","",COUNTIFS(RawData[Date],$A13,RawData[Slot],16)) | T13: =IF($A13="","",COUNTIFS(RawData[Date],$A13,RawData[Slot],17)) | U13: =IF($A13="","",COUNTIFS(RawData[Date],$A13,RawData[Slot],18)) | V13: =IF($A13="","",COUNTIFS(RawData[Date],$A13,RawData[Slot],19)) | W13: =IF($A13="","",COUNTIFS(RawData[Date],$A13,RawData[Slot],20)) | X13: =IF($A13="","",COUNTIFS(RawData[Date],$A13,RawData[Slot],21)) | Y13: =IF($A13="","",COUNTIFS(RawData[Date],$A13,RawData[Slot],22)) | Z13: =IF($A13="","",COUNTIFS(RawData[Date],$A13,RawData[Slot],23)) | AA13: =IF($A13="","",COUNTIFS(RawData[Date],$A13,RawData[Slot],24)) | AB13: =IF($A13="","",COUNTIFS(RawData[Date],$A13,RawData[Slot],25)) | AC13: =IF($A13="","",COUNTIFS(RawData[Date],$A13,RawData[Slot],26)) | AD13: =IF($A13="","",COUNTIFS(RawData[Date],$A13,RawData[Slot],27)) | AE13: =IF($A13="","",COUNTIFS(RawData[Date],$A13,RawData[Slot],28)) | AF13: =IF($A13="","",COUNTIFS(RawData[Date],$A13,RawData[Slot],29)) | AG13: =IF($A13="","",COUNTIFS(RawData[Date],$A13,RawData[Slot],30)) | AH13: =IF($A13="","",COUNTIFS(RawData[Date],$A13,RawData[Slot],31)) | AI13: =IF($A13="","",COUNTIFS(RawData[Date],$A13,RawData[Slot],32)) | AJ13: =IF($A13="","",COUNTIFS(RawData[Date],$A13,RawData[Slot],33)) | AK13: =IF($A13="","",COUNTIFS(RawData[Date],$A13,RawData[Slot],34)) | AL13: =IF($A13="","",COUNTIFS(RawData[Date],$A13,RawData[Slot],35)) | AM13: =IF($A13="","",COUNTIFS(RawData[Date],$A13,RawData[Slot],36)) | AN13: =IF($A13="","",COUNTIFS(RawData[Date],$A13,RawData[Slot],37)) | AO13: =IF($A13="","",COUNTIFS(RawData[Date],$A13,RawData[Slot],38)) | AP13: =IF($A13="","",COUNTIFS(RawData[Date],$A13,RawData[Slot],39)) | AQ13: =IF($A13="","",COUNTIFS(RawData[Date],$A13,RawData[Slot],40)) | AR13: =IF($A13="","",COUNTIFS(RawData[Date],$A13,RawData[Slot],41)) | AS13: =IF($A13="","",COUNTIFS(RawData[Date],$A13,RawData[Slot],42)) | AT13: =IF($A13="","",COUNTIFS(RawData[Date],$A13,RawData[Slot],43)) | AU13: =IF($A13="","",COUNTIFS(RawData[Date],$A13,RawData[Slot],44)) | AV13: =IF($A13="","",COUNTIFS(RawData[Date],$A13,RawData[Slot],45)) | AW13: =IF($A13="","",COUNTIFS(RawData[Date],$A13,RawData[Slot],46)) | AX13: =IF($A13="","",COUNTIFS(RawData[Date],$A13,RawData[Slot],47)) | AY13: =IF(A13="","",SUM(C13:AX13))
B14: =IF(A14="","",CHOOSE(WEEKDAY(A14,2),"Monday","Tuesday","Wednesday","Thursday","Friday","Saturday","Sunday")) | C14: =IF($A14="","",COUNTIFS(RawData[Date],$A14,RawData[Slot],0)) | D14: =IF($A14="","",COUNTIFS(RawData[Date],$A14,RawData[Slot],1)) | E14: =IF($A14="","",COUNTIFS(RawData[Date],$A14,RawData[Slot],2)) | F14: =IF($A14="","",COUNTIFS(RawData[Date],$A14,RawData[Slot],3)) | G14: =IF($A14="","",COUNTIFS(RawData[Date],$A14,RawData[Slot],4)) | H14: =IF($A14="","",COUNTIFS(RawData[Date],$A14,RawData[Slot],5)) | I14: =IF($A14="","",COUNTIFS(RawData[Date],$A14,RawData[Slot],6)) | J14: =IF($A14="","",COUNTIFS(RawData[Date],$A14,RawData[Slot],7)) | K14: =IF($A14="","",COUNTIFS(RawData[Date],$A14,RawData[Slot],8)) | L14: =IF($A14="","",COUNTIFS(RawData[Date],$A14,RawData[Slot],9)) | M14: =IF($A14="","",COUNTIFS(RawData[Date],$A14,RawData[Slot],10)) | N14: =IF($A14="","",COUNTIFS(RawData[Date],$A14,RawData[Slot],11)) | O14: =IF($A14="","",COUNTIFS(RawData[Date],$A14,RawData[Slot],12)) | P14: =IF($A14="","",COUNTIFS(RawData[Date],$A14,RawData[Slot],13)) | Q14: =IF($A14="","",COUNTIFS(RawData[Date],$A14,RawData[Slot],14)) | R14: =IF($A14="","",COUNTIFS(RawData[Date],$A14,RawData[Slot],15)) | S14: =IF($A14="","",COUNTIFS(RawData[Date],$A14,RawData[Slot],16)) | T14: =IF($A14="","",COUNTIFS(RawData[Date],$A14,RawData[Slot],17)) | U14: =IF($A14="","",COUNTIFS(RawData[Date],$A14,RawData[Slot],18)) | V14: =IF($A14="","",COUNTIFS(RawData[Date],$A14,RawData[Slot],19)) | W14: =IF($A14="","",COUNTIFS(RawData[Date],$A14,RawData[Slot],20)) | X14: =IF($A14="","",COUNTIFS(RawData[Date],$A14,RawData[Slot],21)) | Y14: =IF($A14="","",COUNTIFS(RawData[Date],$A14,RawData[Slot],22)) | Z14: =IF($A14="","",COUNTIFS(RawData[Date],$A14,RawData[Slot],23)) | AA14: =IF($A14="","",COUNTIFS(RawData[Date],$A14,RawData[Slot],24)) | AB14: =IF($A14="","",COUNTIFS(RawData[Date],$A14,RawData[Slot],25)) | AC14: =IF($A14="","",COUNTIFS(RawData[Date],$A14,RawData[Slot],26)) | AD14: =IF($A14="","",COUNTIFS(RawData[Date],$A14,RawData[Slot],27)) | AE14: =IF($A14="","",COUNTIFS(RawData[Date],$A14,RawData[Slot],28)) | AF14: =IF($A14="","",COUNTIFS(RawData[Date],$A14,RawData[Slot],29)) | AG14: =IF($A14="","",COUNTIFS(RawData[Date],$A14,RawData[Slot],30)) | AH14: =IF($A14="","",COUNTIFS(RawData[Date],$A14,RawData[Slot],31)) | AI14: =IF($A14="","",COUNTIFS(RawData[Date],$A14,RawData[Slot],32)) | AJ14: =IF($A14="","",COUNTIFS(RawData[Date],$A14,RawData[Slot],33)) | AK14: =IF($A14="","",COUNTIFS(RawData[Date],$A14,RawData[Slot],34)) | AL14: =IF($A14="","",COUNTIFS(RawData[Date],$A14,RawData[Slot],35)) | AM14: =IF($A14="","",COUNTIFS(RawData[Date],$A14,RawData[Slot],36)) | AN14: =IF($A14="","",COUNTIFS(RawData[Date],$A14,RawData[Slot],37)) | AO14: =IF($A14="","",COUNTIFS(RawData[Date],$A14,RawData[Slot],38)) | AP14: =IF($A14="","",COUNTIFS(RawData[Date],$A14,RawData[Slot],39)) | AQ14: =IF($A14="","",COUNTIFS(RawData[Date],$A14,RawData[Slot],40)) | AR14: =IF($A14="","",COUNTIFS(RawData[Date],$A14,RawData[Slot],41)) | AS14: =IF($A14="","",COUNTIFS(RawData[Date],$A14,RawData[Slot],42)) | AT14: =IF($A14="","",COUNTIFS(RawData[Date],$A14,RawData[Slot],43)) | AU14: =IF($A14="","",COUNTIFS(RawData[Date],$A14,RawData[Slot],44)) | AV14: =IF($A14="","",COUNTIFS(RawData[Date],$A14,RawData[Slot],45)) | AW14: =IF($A14="","",COUNTIFS(RawData[Date],$A14,RawData[Slot],46)) | AX14: =IF($A14="","",COUNTIFS(RawData[Date],$A14,RawData[Slot],47)) | AY14: =IF(A14="","",SUM(C14:AX14))
B15: =IF(A15="","",CHOOSE(WEEKDAY(A15,2),"Monday","Tuesday","Wednesday","Thursday","Friday","Saturday","Sunday")) | C15: =IF($A15="","",COUNTIFS(RawData[Date],$A15,RawData[Slot],0)) | D15: =IF($A15="","",COUNTIFS(RawData[Date],$A15,RawData[Slot],1)) | E15: =IF($A15="","",COUNTIFS(RawData[Date],$A15,RawData[Slot],2)) | F15: =IF($A15="","",COUNTIFS(RawData[Date],$A15,RawData[Slot],3)) | G15: =IF($A15="","",COUNTIFS(RawData[Date],$A15,RawData[Slot],4)) | H15: =IF($A15="","",COUNTIFS(RawData[Date],$A15,RawData[Slot],5)) | I15: =IF($A15="","",COUNTIFS(RawData[Date],$A15,RawData[Slot],6)) | J15: =IF($A15="","",COUNTIFS(RawData[Date],$A15,RawData[Slot],7)) | K15: =IF($A15="","",COUNTIFS(RawData[Date],$A15,RawData[Slot],8)) | L15: =IF($A15="","",COUNTIFS(RawData[Date],$A15,RawData[Slot],9)) | M15: =IF($A15="","",COUNTIFS(RawData[Date],$A15,RawData[Slot],10)) | N15: =IF($A15="","",COUNTIFS(RawData[Date],$A15,RawData[Slot],11)) | O15: =IF($A15="","",COUNTIFS(RawData[Date],$A15,RawData[Slot],12)) | P15: =IF($A15="","",COUNTIFS(RawData[Date],$A15,RawData[Slot],13)) | Q15: =IF($A15="","",COUNTIFS(RawData[Date],$A15,RawData[Slot],14)) | R15: =IF($A15="","",COUNTIFS(RawData[Date],$A15,RawData[Slot],15)) | S15: =IF($A15="","",COUNTIFS(RawData[Date],$A15,RawData[Slot],16)) | T15: =IF($A15="","",COUNTIFS(RawData[Date],$A15,RawData[Slot],17)) | U15: =IF($A15="","",COUNTIFS(RawData[Date],$A15,RawData[Slot],18)) | V15: =IF($A15="","",COUNTIFS(RawData[Date],$A15,RawData[Slot],19)) | W15: =IF($A15="","",COUNTIFS(RawData[Date],$A15,RawData[Slot],20)) | X15: =IF($A15="","",COUNTIFS(RawData[Date],$A15,RawData[Slot],21)) | Y15: =IF($A15="","",COUNTIFS(RawData[Date],$A15,RawData[Slot],22)) | Z15: =IF($A15="","",COUNTIFS(RawData[Date],$A15,RawData[Slot],23)) | AA15: =IF($A15="","",COUNTIFS(RawData[Date],$A15,RawData[Slot],24)) | AB15: =IF($A15="","",COUNTIFS(RawData[Date],$A15,RawData[Slot],25)) | AC15: =IF($A15="","",COUNTIFS(RawData[Date],$A15,RawData[Slot],26)) | AD15: =IF($A15="","",COUNTIFS(RawData[Date],$A15,RawData[Slot],27)) | AE15: =IF($A15="","",COUNTIFS(RawData[Date],$A15,RawData[Slot],28)) | AF15: =IF($A15="","",COUNTIFS(RawData[Date],$A15,RawData[Slot],29)) | AG15: =IF($A15="","",COUNTIFS(RawData[Date],$A15,RawData[Slot],30)) | AH15: =IF($A15="","",COUNTIFS(RawData[Date],$A15,RawData[Slot],31)) | AI15: =IF($A15="","",COUNTIFS(RawData[Date],$A15,RawData[Slot],32)) | AJ15: =IF($A15="","",COUNTIFS(RawData[Date],$A15,RawData[Slot],33)) | AK15: =IF($A15="","",COUNTIFS(RawData[Date],$A15,RawData[Slot],34)) | AL15: =IF($A15="","",COUNTIFS(RawData[Date],$A15,RawData[Slot],35)) | AM15: =IF($A15="","",COUNTIFS(RawData[Date],$A15,RawData[Slot],36)) | AN15: =IF($A15="","",COUNTIFS(RawData[Date],$A15,RawData[Slot],37)) | AO15: =IF($A15="","",COUNTIFS(RawData[Date],$A15,RawData[Slot],38)) | AP15: =IF($A15="","",COUNTIFS(RawData[Date],$A15,RawData[Slot],39)) | AQ15: =IF($A15="","",COUNTIFS(RawData[Date],$A15,RawData[Slot],40)) | AR15: =IF($A15="","",COUNTIFS(RawData[Date],$A15,RawData[Slot],41)) | AS15: =IF($A15="","",COUNTIFS(RawData[Date],$A15,RawData[Slot],42)) | AT15: =IF($A15="","",COUNTIFS(RawData[Date],$A15,RawData[Slot],43)) | AU15: =IF($A15="","",COUNTIFS(RawData[Date],$A15,RawData[Slot],44)) | AV15: =IF($A15="","",COUNTIFS(RawData[Date],$A15,RawData[Slot],45)) | AW15: =IF($A15="","",COUNTIFS(RawData[Date],$A15,RawData[Slot],46)) | AX15: =IF($A15="","",COUNTIFS(RawData[Date],$A15,RawData[Slot],47)) | AY15: =IF(A15="","",SUM(C15:AX15))
B16: =IF(A16="","",CHOOSE(WEEKDAY(A16,2),"Monday","Tuesday","Wednesday","Thursday","Friday","Saturday","Sunday")) | C16: =IF($A16="","",COUNTIFS(RawData[Date],$A16,RawData[Slot],0)) | D16: =IF($A16="","",COUNTIFS(RawData[Date],$A16,RawData[Slot],1)) | E16: =IF($A16="","",COUNTIFS(RawData[Date],$A16,RawData[Slot],2)) | F16: =IF($A16="","",COUNTIFS(RawData[Date],$A16,RawData[Slot],3)) | G16: =IF($A16="","",COUNTIFS(RawData[Date],$A16,RawData[Slot],4)) | H16: =IF($A16="","",COUNTIFS(RawData[Date],$A16,RawData[Slot],5)) | I16: =IF($A16="","",COUNTIFS(RawData[Date],$A16,RawData[Slot],6)) | J16: =IF($A16="","",COUNTIFS(RawData[Date],$A16,RawData[Slot],7)) | K16: =IF($A16="","",COUNTIFS(RawData[Date],$A16,RawData[Slot],8)) | L16: =IF($A16="","",COUNTIFS(RawData[Date],$A16,RawData[Slot],9)) | M16: =IF($A16="","",COUNTIFS(RawData[Date],$A16,RawData[Slot],10)) | N16: =IF($A16="","",COUNTIFS(RawData[Date],$A16,RawData[Slot],11)) | O16: =IF($A16="","",COUNTIFS(RawData[Date],$A16,RawData[Slot],12)) | P16: =IF($A16="","",COUNTIFS(RawData[Date],$A16,RawData[Slot],13)) | Q16: =IF($A16="","",COUNTIFS(RawData[Date],$A16,RawData[Slot],14)) | R16: =IF($A16="","",COUNTIFS(RawData[Date],$A16,RawData[Slot],15)) | S16: =IF($A16="","",COUNTIFS(RawData[Date],$A16,RawData[Slot],16)) | T16: =IF($A16="","",COUNTIFS(RawData[Date],$A16,RawData[Slot],17)) | U16: =IF($A16="","",COUNTIFS(RawData[Date],$A16,RawData[Slot],18)) | V16: =IF($A16="","",COUNTIFS(RawData[Date],$A16,RawData[Slot],19)) | W16: =IF($A16="","",COUNTIFS(RawData[Date],$A16,RawData[Slot],20)) | X16: =IF($A16="","",COUNTIFS(RawData[Date],$A16,RawData[Slot],21)) | Y16: =IF($A16="","",COUNTIFS(RawData[Date],$A16,RawData[Slot],22)) | Z16: =IF($A16="","",COUNTIFS(RawData[Date],$A16,RawData[Slot],23)) | AA16: =IF($A16="","",COUNTIFS(RawData[Date],$A16,RawData[Slot],24)) | AB16: =IF($A16="","",COUNTIFS(RawData[Date],$A16,RawData[Slot],25)) | AC16: =IF($A16="","",COUNTIFS(RawData[Date],$A16,RawData[Slot],26)) | AD16: =IF($A16="","",COUNTIFS(RawData[Date],$A16,RawData[Slot],27)) | AE16: =IF($A16="","",COUNTIFS(RawData[Date],$A16,RawData[Slot],28)) | AF16: =IF($A16="","",COUNTIFS(RawData[Date],$A16,RawData[Slot],29)) | AG16: =IF($A16="","",COUNTIFS(RawData[Date],$A16,RawData[Slot],30)) | AH16: =IF($A16="","",COUNTIFS(RawData[Date],$A16,RawData[Slot],31)) | AI16: =IF($A16="","",COUNTIFS(RawData[Date],$A16,RawData[Slot],32)) | AJ16: =IF($A16="","",COUNTIFS(RawData[Date],$A16,RawData[Slot],33)) | AK16: =IF($A16="","",COUNTIFS(RawData[Date],$A16,RawData[Slot],34)) | AL16: =IF($A16="","",COUNTIFS(RawData[Date],$A16,RawData[Slot],35)) | AM16: =IF($A16="","",COUNTIFS(RawData[Date],$A16,RawData[Slot],36)) | AN16: =IF($A16="","",COUNTIFS(RawData[Date],$A16,RawData[Slot],37)) | AO16: =IF($A16="","",COUNTIFS(RawData[Date],$A16,RawData[Slot],38)) | AP16: =IF($A16="","",COUNTIFS(RawData[Date],$A16,RawData[Slot],39)) | AQ16: =IF($A16="","",COUNTIFS(RawData[Date],$A16,RawData[Slot],40)) | AR16: =IF($A16="","",COUNTIFS(RawData[Date],$A16,RawData[Slot],41)) | AS16: =IF($A16="","",COUNTIFS(RawData[Date],$A16,RawData[Slot],42)) | AT16: =IF($A16="","",COUNTIFS(RawData[Date],$A16,RawData[Slot],43)) | AU16: =IF($A16="","",COUNTIFS(RawData[Date],$A16,RawData[Slot],44)) | AV16: =IF($A16="","",COUNTIFS(RawData[Date],$A16,RawData[Slot],45)) | AW16: =IF($A16="","",COUNTIFS(RawData[Date],$A16,RawData[Slot],46)) | AX16: =IF($A16="","",COUNTIFS(RawData[Date],$A16,RawData[Slot],47)) | AY16: =IF(A16="","",SUM(C16:AX16))
B17: =IF(A17="","",CHOOSE(WEEKDAY(A17,2),"Monday","Tuesday","Wednesday","Thursday","Friday","Saturday","Sunday")) | C17: =IF($A17="","",COUNTIFS(RawData[Date],$A17,RawData[Slot],0)) | D17: =IF($A17="","",COUNTIFS(RawData[Date],$A17,RawData[Slot],1)) | E17: =IF($A17="","",COUNTIFS(RawData[Date],$A17,RawData[Slot],2)) | F17: =IF($A17="","",COUNTIFS(RawData[Date],$A17,RawData[Slot],3)) | G17: =IF($A17="","",COUNTIFS(RawData[Date],$A17,RawData[Slot],4)) | H17: =IF($A17="","",COUNTIFS(RawData[Date],$A17,RawData[Slot],5)) | I17: =IF($A17="","",COUNTIFS(RawData[Date],$A17,RawData[Slot],6)) | J17: =IF($A17="","",COUNTIFS(RawData[Date],$A17,RawData[Slot],7)) | K17: =IF($A17="","",COUNTIFS(RawData[Date],$A17,RawData[Slot],8)) | L17: =IF($A17="","",COUNTIFS(RawData[Date],$A17,RawData[Slot],9)) | M17: =IF($A17="","",COUNTIFS(RawData[Date],$A17,RawData[Slot],10)) | N17: =IF($A17="","",COUNTIFS(RawData[Date],$A17,RawData[Slot],11)) | O17: =IF($A17="","",COUNTIFS(RawData[Date],$A17,RawData[Slot],12)) | P17: =IF($A17="","",COUNTIFS(RawData[Date],$A17,RawData[Slot],13)) | Q17: =IF($A17="","",COUNTIFS(RawData[Date],$A17,RawData[Slot],14)) | R17: =IF($A17="","",COUNTIFS(RawData[Date],$A17,RawData[Slot],15)) | S17: =IF($A17="","",COUNTIFS(RawData[Date],$A17,RawData[Slot],16)) | T17: =IF($A17="","",COUNTIFS(RawData[Date],$A17,RawData[Slot],17)) | U17: =IF($A17="","",COUNTIFS(RawData[Date],$A17,RawData[Slot],18)) | V17: =IF($A17="","",COUNTIFS(RawData[Date],$A17,RawData[Slot],19)) | W17: =IF($A17="","",COUNTIFS(RawData[Date],$A17,RawData[Slot],20)) | X17: =IF($A17="","",COUNTIFS(RawData[Date],$A17,RawData[Slot],21)) | Y17: =IF($A17="","",COUNTIFS(RawData[Date],$A17,RawData[Slot],22)) | Z17: =IF($A17="","",COUNTIFS(RawData[Date],$A17,RawData[Slot],23)) | AA17: =IF($A17="","",COUNTIFS(RawData[Date],$A17,RawData[Slot],24)) | AB17: =IF($A17="","",COUNTIFS(RawData[Date],$A17,RawData[Slot],25)) | AC17: =IF($A17="","",COUNTIFS(RawData[Date],$A17,RawData[Slot],26)) | AD17: =IF($A17="","",COUNTIFS(RawData[Date],$A17,RawData[Slot],27)) | AE17: =IF($A17="","",COUNTIFS(RawData[Date],$A17,RawData[Slot],28)) | AF17: =IF($A17="","",COUNTIFS(RawData[Date],$A17,RawData[Slot],29)) | AG17: =IF($A17="","",COUNTIFS(RawData[Date],$A17,RawData[Slot],30)) | AH17: =IF($A17="","",COUNTIFS(RawData[Date],$A17,RawData[Slot],31)) | AI17: =IF($A17="","",COUNTIFS(RawData[Date],$A17,RawData[Slot],32)) | AJ17: =IF($A17="","",COUNTIFS(RawData[Date],$A17,RawData[Slot],33)) | AK17: =IF($A17="","",COUNTIFS(RawData[Date],$A17,RawData[Slot],34)) | AL17: =IF($A17="","",COUNTIFS(RawData[Date],$A17,RawData[Slot],35)) | AM17: =IF($A17="","",COUNTIFS(RawData[Date],$A17,RawData[Slot],36)) | AN17: =IF($A17="","",COUNTIFS(RawData[Date],$A17,RawData[Slot],37)) | AO17: =IF($A17="","",COUNTIFS(RawData[Date],$A17,RawData[Slot],38)) | AP17: =IF($A17="","",COUNTIFS(RawData[Date],$A17,RawData[Slot],39)) | AQ17: =IF($A17="","",COUNTIFS(RawData[Date],$A17,RawData[Slot],40)) | AR17: =IF($A17="","",COUNTIFS(RawData[Date],$A17,RawData[Slot],41)) | AS17: =IF($A17="","",COUNTIFS(RawData[Date],$A17,RawData[Slot],42)) | AT17: =IF($A17="","",COUNTIFS(RawData[Date],$A17,RawData[Slot],43)) | AU17: =IF($A17="","",COUNTIFS(RawData[Date],$A17,RawData[Slot],44)) | AV17: =IF($A17="","",COUNTIFS(RawData[Date],$A17,RawData[Slot],45)) | AW17: =IF($A17="","",COUNTIFS(RawData[Date],$A17,RawData[Slot],46)) | AX17: =IF($A17="","",COUNTIFS(RawData[Date],$A17,RawData[Slot],47)) | AY17: =IF(A17="","",SUM(C17:AX17))
B18: =IF(A18="","",CHOOSE(WEEKDAY(A18,2),"Monday","Tuesday","Wednesday","Thursday","Friday","Saturday","Sunday")) | C18: =IF($A18="","",COUNTIFS(RawData[Date],$A18,RawData[Slot],0)) | D18: =IF($A18="","",COUNTIFS(RawData[Date],$A18,RawData[Slot],1)) | E18: =IF($A18="","",COUNTIFS(RawData[Date],$A18,RawData[Slot],2)) | F18: =IF($A18="","",COUNTIFS(RawData[Date],$A18,RawData[Slot],3)) | G18: =IF($A18="","",COUNTIFS(RawData[Date],$A18,RawData[Slot],4)) | H18: =IF($A18="","",COUNTIFS(RawData[Date],$A18,RawData[Slot],5)) | I18: =IF($A18="","",COUNTIFS(RawData[Date],$A18,RawData[Slot],6)) | J18: =IF($A18="","",COUNTIFS(RawData[Date],$A18,RawData[Slot],7)) | K18: =IF($A18="","",COUNTIFS(RawData[Date],$A18,RawData[Slot],8)) | L18: =IF($A18="","",COUNTIFS(RawData[Date],$A18,RawData[Slot],9)) | M18: =IF($A18="","",COUNTIFS(RawData[Date],$A18,RawData[Slot],10)) | N18: =IF($A18="","",COUNTIFS(RawData[Date],$A18,RawData[Slot],11)) | O18: =IF($A18="","",COUNTIFS(RawData[Date],$A18,RawData[Slot],12)) | P18: =IF($A18="","",COUNTIFS(RawData[Date],$A18,RawData[Slot],13)) | Q18: =IF($A18="","",COUNTIFS(RawData[Date],$A18,RawData[Slot],14)) | R18: =IF($A18="","",COUNTIFS(RawData[Date],$A18,RawData[Slot],15)) | S18: =IF($A18="","",COUNTIFS(RawData[Date],$A18,RawData[Slot],16)) | T18: =IF($A18="","",COUNTIFS(RawData[Date],$A18,RawData[Slot],17)) | U18: =IF($A18="","",COUNTIFS(RawData[Date],$A18,RawData[Slot],18)) | V18: =IF($A18="","",COUNTIFS(RawData[Date],$A18,RawData[Slot],19)) | W18: =IF($A18="","",COUNTIFS(RawData[Date],$A18,RawData[Slot],20)) | X18: =IF($A18="","",COUNTIFS(RawData[Date],$A18,RawData[Slot],21)) | Y18: =IF($A18="","",COUNTIFS(RawData[Date],$A18,RawData[Slot],22)) | Z18: =IF($A18="","",COUNTIFS(RawData[Date],$A18,RawData[Slot],23)) | AA18: =IF($A18="","",COUNTIFS(RawData[Date],$A18,RawData[Slot],24)) | AB18: =IF($A18="","",COUNTIFS(RawData[Date],$A18,RawData[Slot],25)) | AC18: =IF($A18="","",COUNTIFS(RawData[Date],$A18,RawData[Slot],26)) | AD18: =IF($A18="","",COUNTIFS(RawData[Date],$A18,RawData[Slot],27)) | AE18: =IF($A18="","",COUNTIFS(RawData[Date],$A18,RawData[Slot],28)) | AF18: =IF($A18="","",COUNTIFS(RawData[Date],$A18,RawData[Slot],29)) | AG18: =IF($A18="","",COUNTIFS(RawData[Date],$A18,RawData[Slot],30)) | AH18: =IF($A18="","",COUNTIFS(RawData[Date],$A18,RawData[Slot],31)) | AI18: =IF($A18="","",COUNTIFS(RawData[Date],$A18,RawData[Slot],32)) | AJ18: =IF($A18="","",COUNTIFS(RawData[Date],$A18,RawData[Slot],33)) | AK18: =IF($A18="","",COUNTIFS(RawData[Date],$A18,RawData[Slot],34)) | AL18: =IF($A18="","",COUNTIFS(RawData[Date],$A18,RawData[Slot],35)) | AM18: =IF($A18="","",COUNTIFS(RawData[Date],$A18,RawData[Slot],36)) | AN18: =IF($A18="","",COUNTIFS(RawData[Date],$A18,RawData[Slot],37)) | AO18: =IF($A18="","",COUNTIFS(RawData[Date],$A18,RawData[Slot],38)) | AP18: =IF($A18="","",COUNTIFS(RawData[Date],$A18,RawData[Slot],39)) | AQ18: =IF($A18="","",COUNTIFS(RawData[Date],$A18,RawData[Slot],40)) | AR18: =IF($A18="","",COUNTIFS(RawData[Date],$A18,RawData[Slot],41)) | AS18: =IF($A18="","",COUNTIFS(RawData[Date],$A18,RawData[Slot],42)) | AT18: =IF($A18="","",COUNTIFS(RawData[Date],$A18,RawData[Slot],43)) | AU18: =IF($A18="","",COUNTIFS(RawData[Date],$A18,RawData[Slot],44)) | AV18: =IF($A18="","",COUNTIFS(RawData[Date],$A18,RawData[Slot],45)) | AW18: =IF($A18="","",COUNTIFS(RawData[Date],$A18,RawData[Slot],46)) | AX18: =IF($A18="","",COUNTIFS(RawData[Date],$A18,RawData[Slot],47)) | AY18: =IF(A18="","",SUM(C18:AX18))
B19: =IF(A19="","",CHOOSE(WEEKDAY(A19,2),"Monday","Tuesday","Wednesday","Thursday","Friday","Saturday","Sunday")) | C19: =IF($A19="","",COUNTIFS(RawData[Date],$A19,RawData[Slot],0)) | D19: =IF($A19="","",COUNTIFS(RawData[Date],$A19,RawData[Slot],1)) | E19: =IF($A19="","",COUNTIFS(RawData[Date],$A19,RawData[Slot],2)) | F19: =IF($A19="","",COUNTIFS(RawData[Date],$A19,RawData[Slot],3)) | G19: =IF($A19="","",COUNTIFS(RawData[Date],$A19,RawData[Slot],4)) | H19: =IF($A19="","",COUNTIFS(RawData[Date],$A19,RawData[Slot],5)) | I19: =IF($A19="","",COUNTIFS(RawData[Date],$A19,RawData[Slot],6)) | J19: =IF($A19="","",COUNTIFS(RawData[Date],$A19,RawData[Slot],7)) | K19: =IF($A19="","",COUNTIFS(RawData[Date],$A19,RawData[Slot],8)) | L19: =IF($A19="","",COUNTIFS(RawData[Date],$A19,RawData[Slot],9)) | M19: =IF($A19="","",COUNTIFS(RawData[Date],$A19,RawData[Slot],10)) | N19: =IF($A19="","",COUNTIFS(RawData[Date],$A19,RawData[Slot],11)) | O19: =IF($A19="","",COUNTIFS(RawData[Date],$A19,RawData[Slot],12)) | P19: =IF($A19="","",COUNTIFS(RawData[Date],$A19,RawData[Slot],13)) | Q19: =IF($A19="","",COUNTIFS(RawData[Date],$A19,RawData[Slot],14)) | R19: =IF($A19="","",COUNTIFS(RawData[Date],$A19,RawData[Slot],15)) | S19: =IF($A19="","",COUNTIFS(RawData[Date],$A19,RawData[Slot],16)) | T19: =IF($A19="","",COUNTIFS(RawData[Date],$A19,RawData[Slot],17)) | U19: =IF($A19="","",COUNTIFS(RawData[Date],$A19,RawData[Slot],18)) | V19: =IF($A19="","",COUNTIFS(RawData[Date],$A19,RawData[Slot],19)) | W19: =IF($A19="","",COUNTIFS(RawData[Date],$A19,RawData[Slot],20)) | X19: =IF($A19="","",COUNTIFS(RawData[Date],$A19,RawData[Slot],21)) | Y19: =IF($A19="","",COUNTIFS(RawData[Date],$A19,RawData[Slot],22)) | Z19: =IF($A19="","",COUNTIFS(RawData[Date],$A19,RawData[Slot],23)) | AA19: =IF($A19="","",COUNTIFS(RawData[Date],$A19,RawData[Slot],24)) | AB19: =IF($A19="","",COUNTIFS(RawData[Date],$A19,RawData[Slot],25)) | AC19: =IF($A19="","",COUNTIFS(RawData[Date],$A19,RawData[Slot],26)) | AD19: =IF($A19="","",COUNTIFS(RawData[Date],$A19,RawData[Slot],27)) | AE19: =IF($A19="","",COUNTIFS(RawData[Date],$A19,RawData[Slot],28)) | AF19: =IF($A19="","",COUNTIFS(RawData[Date],$A19,RawData[Slot],29)) | AG19: =IF($A19="","",COUNTIFS(RawData[Date],$A19,RawData[Slot],30)) | AH19: =IF($A19="","",COUNTIFS(RawData[Date],$A19,RawData[Slot],31)) | AI19: =IF($A19="","",COUNTIFS(RawData[Date],$A19,RawData[Slot],32)) | AJ19: =IF($A19="","",COUNTIFS(RawData[Date],$A19,RawData[Slot],33)) | AK19: =IF($A19="","",COUNTIFS(RawData[Date],$A19,RawData[Slot],34)) | AL19: =IF($A19="","",COUNTIFS(RawData[Date],$A19,RawData[Slot],35)) | AM19: =IF($A19="","",COUNTIFS(RawData[Date],$A19,RawData[Slot],36)) | AN19: =IF($A19="","",COUNTIFS(RawData[Date],$A19,RawData[Slot],37)) | AO19: =IF($A19="","",COUNTIFS(RawData[Date],$A19,RawData[Slot],38)) | AP19: =IF($A19="","",COUNTIFS(RawData[Date],$A19,RawData[Slot],39)) | AQ19: =IF($A19="","",COUNTIFS(RawData[Date],$A19,RawData[Slot],40)) | AR19: =IF($A19="","",COUNTIFS(RawData[Date],$A19,RawData[Slot],41)) | AS19: =IF($A19="","",COUNTIFS(RawData[Date],$A19,RawData[Slot],42)) | AT19: =IF($A19="","",COUNTIFS(RawData[Date],$A19,RawData[Slot],43)) | AU19: =IF($A19="","",COUNTIFS(RawData[Date],$A19,RawData[Slot],44)) | AV19: =IF($A19="","",COUNTIFS(RawData[Date],$A19,RawData[Slot],45)) | AW19: =IF($A19="","",COUNTIFS(RawData[Date],$A19,RawData[Slot],46)) | AX19: =IF($A19="","",COUNTIFS(RawData[Date],$A19,RawData[Slot],47)) | AY19: =IF(A19="","",SUM(C19:AX19))
B20: =IF(A20="","",CHOOSE(WEEKDAY(A20,2),"Monday","Tuesday","Wednesday","Thursday","Friday","Saturday","Sunday")) | C20: =IF($A20="","",COUNTIFS(RawData[Date],$A20,RawData[Slot],0)) | D20: =IF($A20="","",COUNTIFS(RawData[Date],$A20,RawData[Slot],1)) | E20: =IF($A20="","",COUNTIFS(RawData[Date],$A20,RawData[Slot],2)) | F20: =IF($A20="","",COUNTIFS(RawData[Date],$A20,RawData[Slot],3)) | G20: =IF($A20="","",COUNTIFS(RawData[Date],$A20,RawData[Slot],4)) | H20: =IF($A20="","",COUNTIFS(RawData[Date],$A20,RawData[Slot],5)) | I20: =IF($A20="","",COUNTIFS(RawData[Date],$A20,RawData[Slot],6)) | J20: =IF($A20="","",COUNTIFS(RawData[Date],$A20,RawData[Slot],7)) | K20: =IF($A20="","",COUNTIFS(RawData[Date],$A20,RawData[Slot],8)) | L20: =IF($A20="","",COUNTIFS(RawData[Date],$A20,RawData[Slot],9)) | M20: =IF($A20="","",COUNTIFS(RawData[Date],$A20,RawData[Slot],10)) | N20: =IF($A20="","",COUNTIFS(RawData[Date],$A20,RawData[Slot],11)) | O20: =IF($A20="","",COUNTIFS(RawData[Date],$A20,RawData[Slot],12)) | P20: =IF($A20="","",COUNTIFS(RawData[Date],$A20,RawData[Slot],13)) | Q20: =IF($A20="","",COUNTIFS(RawData[Date],$A20,RawData[Slot],14)) | R20: =IF($A20="","",COUNTIFS(RawData[Date],$A20,RawData[Slot],15)) | S20: =IF($A20="","",COUNTIFS(RawData[Date],$A20,RawData[Slot],16)) | T20: =IF($A20="","",COUNTIFS(RawData[Date],$A20,RawData[Slot],17)) | U20: =IF($A20="","",COUNTIFS(RawData[Date],$A20,RawData[Slot],18)) | V20: =IF($A20="","",COUNTIFS(RawData[Date],$A20,RawData[Slot],19)) | W20: =IF($A20="","",COUNTIFS(RawData[Date],$A20,RawData[Slot],20)) | X20: =IF($A20="","",COUNTIFS(RawData[Date],$A20,RawData[Slot],21)) | Y20: =IF($A20="","",COUNTIFS(RawData[Date],$A20,RawData[Slot],22)) | Z20: =IF($A20="","",COUNTIFS(RawData[Date],$A20,RawData[Slot],23)) | AA20: =IF($A20="","",COUNTIFS(RawData[Date],$A20,RawData[Slot],24)) | AB20: =IF($A20="","",COUNTIFS(RawData[Date],$A20,RawData[Slot],25)) | AC20: =IF($A20="","",COUNTIFS(RawData[Date],$A20,RawData[Slot],26)) | AD20: =IF($A20="","",COUNTIFS(RawData[Date],$A20,RawData[Slot],27)) | AE20: =IF($A20="","",COUNTIFS(RawData[Date],$A20,RawData[Slot],28)) | AF20: =IF($A20="","",COUNTIFS(RawData[Date],$A20,RawData[Slot],29)) | AG20: =IF($A20="","",COUNTIFS(RawData[Date],$A20,RawData[Slot],30)) | AH20: =IF($A20="","",COUNTIFS(RawData[Date],$A20,RawData[Slot],31)) | AI20: =IF($A20="","",COUNTIFS(RawData[Date],$A20,RawData[Slot],32)) | AJ20: =IF($A20="","",COUNTIFS(RawData[Date],$A20,RawData[Slot],33)) | AK20: =IF($A20="","",COUNTIFS(RawData[Date],$A20,RawData[Slot],34)) | AL20: =IF($A20="","",COUNTIFS(RawData[Date],$A20,RawData[Slot],35)) | AM20: =IF($A20="","",COUNTIFS(RawData[Date],$A20,RawData[Slot],36)) | AN20: =IF($A20="","",COUNTIFS(RawData[Date],$A20,RawData[Slot],37)) | AO20: =IF($A20="","",COUNTIFS(RawData[Date],$A20,RawData[Slot],38)) | AP20: =IF($A20="","",COUNTIFS(RawData[Date],$A20,RawData[Slot],39)) | AQ20: =IF($A20="","",COUNTIFS(RawData[Date],$A20,RawData[Slot],40)) | AR20: =IF($A20="","",COUNTIFS(RawData[Date],$A20,RawData[Slot],41)) | AS20: =IF($A20="","",COUNTIFS(RawData[Date],$A20,RawData[Slot],42)) | AT20: =IF($A20="","",COUNTIFS(RawData[Date],$A20,RawData[Slot],43)) | AU20: =IF($A20="","",COUNTIFS(RawData[Date],$A20,RawData[Slot],44)) | AV20: =IF($A20="","",COUNTIFS(RawData[Date],$A20,RawData[Slot],45)) | AW20: =IF($A20="","",COUNTIFS(RawData[Date],$A20,RawData[Slot],46)) | AX20: =IF($A20="","",COUNTIFS(RawData[Date],$A20,RawData[Slot],47)) | AY20: =IF(A20="","",SUM(C20:AX20))
